Workbook

Sheet Project Assumptions
A1: Project Assumptions
A3: Business Objective | B3: Data Structure
A4: Determine whether incoming ticket demand exceeded the team's processing capacity during the analysis period and identify factors contributing to backlog growth. | B4: Status, Priority, Team, and Ticket Type are selected from dropdown menus to ensure category consistency.
A5: Analysis Scope | B5: Data Quality Checks
A6: Analysis Period: January - March | B6: The dataset was validated for:
A7: Records Analyzed: 399 | B7: Missing values
A8: Tool Used: Excel | B8: Duplicate Ticket IDs
A9: Dataset Type: Simulated (based on a real business process) | B9: Invalid dates
B10: Resolution date inconsistencies
B11: Negative resolution times
A12: Key Assumptions | B12: Project Limitations
A13: Ticket IDs are unique identifiers. | B13: Historical backlog data was unavailable.
A14: Blank resolution dates are valid for open tickets. | B14: The dashboard measures backlog accumulated during the analysis period only.
A15: Weeks start on Monday.
A16: Resolution time is measured in hours. | B16: The dataset was recreated for portfolio purposes and does not contain confidential information.
A17: Backlog represents the analysis period only.
A20: KPI Definitions
A22: KPI | B22: Definition
A23: Incoming Tickets | B23: Total tickets received during the analysis period.
A24: Completed Tickets | B24: Total tickets resolved during the analysis period.
A25: Backlog | B25: Cumulative difference between incoming and completed tickets during the analysis period.
A26: Avg Resolution Time | B26: Average resolution time for completed tickets (hours).

Sheet 00_Raw_Data
A1: Raw Ticket Dataset
A3: ticket_id | B3: creation_date | C3: resolution_date | D3: status | E3: ticket_type | F3: priority | G3: team | H3: resolution_time_hours
A4: 1 | B4: 45301 | D4: Open | E4: Series | F4: Medium | G4: Team A
A5: 2 | B5: 45329 | D5: Open | E5: Movie | F5: Medium | G5: Team B
A6: 3 | B6: 45307 | D6: Open | E6: Movie | F6: Medium | G6: Team B
A7: 4 | B7: 45336 | D7: Open | E7: Series | F7: Medium | G7: Team B
A8: 5 | B8: 45333 | D8: Open | E8: Series | F8: Medium | G8: Team B
A9: 6 | B9: 45292 | D9: Open | E9: Series | F9: Low | G9: Team A
A10: 7 | B10: 45369 | D10: Closed | E10: Movie | F10: Low | G10: Team B | H10: 216
A11: 8 | B11: 45331 | D11: Open | E11: Series | F11: Medium | G11: Team B
A12: 9 | B12: 45330 | D12: Open | E12: Movie | F12: High | G12: Team A
A13: 10 | B13: 45298 | C13: 45305 | D13: Closed | E13: Series | F13: Medium | G13: Team A | H13: 168
A14: 11 | B14: 45344 | D14: Open | E14: Series | F14: Medium | G14: Team B
A15: 12 | B15: 45304 | D15: Open | E15: Series | F15: Medium | G15: Team B
A16: 13 | B16: 45324 | D16: Closed | E16: Series | F16: High | G16: Team B | H16: 48
A17: 14 | B17: 45353 | D17: Open | E17: Series | F17: Medium | G17: Team A
A18: 15 | B18: 45338 | D18: Open | E18: Series | F18: Medium | G18: Team B
A19: 16 | B19: 45300 | D19: Open | E19: Movie | F19: Medium | G19: Team A
A20: 17 | B20: 45337 | D20: Open | E20: Series | F20: High | G20: Team A
A21: 18 | B21: 45357 | D21: Open | E21: Series | F21: Medium | G21: Team A
A22: 19 | B22: 45369 | D22: Open | E22: Movie | F22: Medium | G22: Team B
A23: 20 | B23: 45299 | C23: 45300 | D23: Closed | E23: Movie | F23: High | G23: Team B | H23: 24
A24: 21 | B24: 45298 | C24: 45296 | D24: Closed | E24: Movie | F24: Medium | G24: Team A | H24: 144
A25: 22 | B25: 45310 | D25: Open | E25: Series | F25: High | G25: Team A
A26: 23 | B26: 45309 | D26: Open | E26: Series | F26: Medium | G26: Team B
A27: 24 | B27: 45376 | D27: Open | E27: Movie | F27: Medium | G27: Team B
A28: 25 | B28: 45302 | C28: 45301 | D28: Closed | E28: Series | F28: High | G28: Team B | H28: 168
A29: 26 | B29: 45298 | D29: Open | E29: Movie | F29: Low | G29: Team B
A30: 27 | B30: 45323 | D30: Open | E30: Movie | F30: Low | G30: Team B
A31: 28 | B31: 45348 | D31: Open | E31: Movie | F31: Medium | G31: Team A
A32: 29 | B32: 45376 | D32: Open | E32: Series | F32: High | G32: Team B
A33: 30 | B33: 45380 | D33: Open | E33: Movie | F33: Medium | G33: Team B
A34: 31 | B34: 45334 | D34: Open | E34: Movie | F34: Medium | G34: Team A
A35: 32 | B35: 45335 | D35: Open | E35: Series | F35: Medium | G35: Team A
A36: 33 | B36: 45311 | D36: Open | E36: Series | F36: High | G36: Team B
A37: 34 | B37: 45323 | D37: Open | E37: Series | F37: Medium | G37: Team A
A38: 35 | B38: 45373 | D38: Open | E38: Movie | F38: Low | G38: Team B
A39: 36 | B39: 45327 | C39: 45331 | D39: Closed | E39: Movie | F39: Medium | G39: Team B | H39: 96
A40: 37 | B40: 45308 | C40: 45312 | D40: Closed | E40: Movie | F40: Medium | G40: Team A | H40: 96
A41: 38 | B41: 45302 | C41: 45306 | D41: Closed | E41: Series | F41: Medium | G41: Team B | H41: 96
...

Sheet 01_Data_Audit
A1: Data Quality Audit
A3: Data Quality Summary
A4: Records Audited | B4: 399
A5: Validation Checks | B5: 10
A6: Passed | B6: 8
A7: Failed | B7: 2
A10: Category | B10: Validation | C10: Description | D10: Result | E10: Status | F10: Comments
A11: Completeness | B11: Total Records | C11: Verify the total number of records in the dataset | D11: =COUNTA('00_Raw_Data'!A:A)-1 -> 400 | E11: PASS
B12: Blank Ticket IDs | C12: Verify that every ticket has a valid ID | D12: =COUNTBLANK('00_Raw_Data'!A4:A402) -> 0 | E12: PASS
B13: Blank Creation Dates | C13: Verify that all tickets have a creation date | D13: =COUNTBLANK('00_Raw_Data'!B4:B402) -> 0 | E13: PASS
A14: Uniqueness | B14: Duplicate Ticket IDs | C14: Verify that each ticket has a unique ID | D14: {=COUNTA('00_Raw_Data'!A4:A1012)-COUNTA(_xludf.UNIQUE('00_Raw_Data'!A4:A1012))} -> 398 | E14: PASS
A15: Business Rules | B15: Closed Tickets Without Resolution Date | C15: Verify that all closed tickets have a resolution date | D15: =COUNTIFS('00_Raw_Data'!D4:D402,"Closed",'00_Raw_Data'!C4:C402,"") -> 4 | E15: FAIL | F15: Four manually entered records were missing a resolution date
B16: Resolution Before Creation Date | C16: Verify that resolution dates are not earlier than creation dates | D16: {=SUM(IF(('00_Raw_Data'!C4:C402<>"")*('00_Raw_Data'!C4:C402<'00_Raw_Data'!B4:B402),1,0))} -> 2 | E16: FAIL | F16: Two records contained inconsistent chronological dates
A17: Consistency | B17: Invalid Creation Dates | C17: Verify that all creation dates are valid date values | D17: {=SUM(IF(('00_Raw_Data'!B4:B402<>"")*(NOT(ISNUMBER('00_Raw_Data'!B4:B402))),1,0))} -> 0 | E17: PASS
B18: Invalid Resolution Dates | C18: Verify that all resolution dates are valid date values | D18: {=SUM(IF(('00_Raw_Data'!C4:C402<>"")*(NOT(ISNUMBER('00_Raw_Data'!C4:C402))),1,0))} -> 0 | E18: PASS
B19: Invalid Resolution Hours | C19: Verify that all resolution time values are numeric | D19: {=SUM(IF(('00_Raw_Data'!H4:H402<>"")*(NOT(ISNUMBER('00_Raw_Data'!H4:H402))),1,0))} -> 0 | E19: PASS
B20: Negative Resolution Hours | C20: Verify that resolution time values are zero or greater | D20: =COUNTIF('00_Raw_Data'!H4:H402,"<0") -> 0 | E20: PASS

Sheet 02_Prepared_Data
A1: Clean Ticket Dataset
A3: ticket_id | B3: creation_date | C3: resolution_date | D3: status | E3: ticket_type | F3: priority | G3: team | H3: resolution_time_hours | I3: creation_week | J3: resolution_week | K3: creation_month | L3: resolution_month | O3: Validations
A4: 1 | B4: 45301 | D4: Open | E4: Series | F4: Medium | G4: Team A | I4: =WEEKNUM(B4,2) -> 2 | J4: =IF(C4="","",WEEKNUM(C4,2)) | K4: =VLOOKUP(MONTH(B4),'03_Lookup'!A:B,2,FALSE) -> Jan | L4: =IF(C4="","",VLOOKUP(MONTH(C4),'03_Lookup'!A:B,2,FALSE)) | O4: =ISNUMBER(B4) -> TRUE
A5: 2 | B5: 45329 | D5: Open | E5: Movie | F5: Medium | G5: Team B | I5: =WEEKNUM(B5,2) -> 6 | J5: =IF(C5="","",WEEKNUM(C5,2)) | K5: =VLOOKUP(MONTH(B5),'03_Lookup'!A:B,2,FALSE) -> Feb | L5: =IF(C5="","",VLOOKUP(MONTH(C5),'03_Lookup'!A:B,2,FALSE)) | O5: =ISNUMBER(C13) -> TRUE
A6: 3 | B6: 45307 | D6: Open | E6: Movie | F6: Medium | G6: Team B | I6: =WEEKNUM(B6,2) -> 3 | J6: =IF(C6="","",WEEKNUM(C6,2)) | K6: =VLOOKUP(MONTH(B6),'03_Lookup'!A:B,2,FALSE) -> Jan | L6: =IF(C6="","",VLOOKUP(MONTH(C6),'03_Lookup'!A:B,2,FALSE)) | O6: =C24<B24 -> TRUE
A7: 4 | B7: 45336 | D7: Open | E7: Series | F7: Medium | G7: Team B | I7: =WEEKNUM(B7,2) -> 7 | J7: =IF(C7="","",WEEKNUM(C7,2)) | K7: =VLOOKUP(MONTH(B7),'03_Lookup'!A:B,2,FALSE) -> Feb | L7: =IF(C7="","",VLOOKUP(MONTH(C7),'03_Lookup'!A:B,2,FALSE))
A8: 5 | B8: 45333 | D8: Open | E8: Series | F8: Medium | G8: Team B | I8: =WEEKNUM(B8,2) -> 6 | J8: =IF(C8="","",WEEKNUM(C8,2)) | K8: =VLOOKUP(MONTH(B8),'03_Lookup'!A:B,2,FALSE) -> Feb | L8: =IF(C8="","",VLOOKUP(MONTH(C8),'03_Lookup'!A:B,2,FALSE))
A9: 6 | B9: 45292 | D9: Open | E9: Series | F9: Low | G9: Team A | I9: =WEEKNUM(B9,2) -> 1 | J9: =IF(C9="","",WEEKNUM(C9,2)) | K9: =VLOOKUP(MONTH(B9),'03_Lookup'!A:B,2,FALSE) -> Jan | L9: =IF(C9="","",VLOOKUP(MONTH(C9),'03_Lookup'!A:B,2,FALSE))
A10: 7 | B10: 45369 | D10: Closed | E10: Movie | F10: Low | G10: Team B | H10: 216 | I10: =WEEKNUM(B10,2) -> 12 | J10: =IF(C10="","",WEEKNUM(C10,2)) | K10: =VLOOKUP(MONTH(B10),'03_Lookup'!A:B,2,FALSE) -> Mar | L10: =IF(C10="","",VLOOKUP(MONTH(C10),'03_Lookup'!A:B,2,FALSE))
A11: 8 | B11: 45331 | D11: Open | E11: Series | F11: Medium | G11: Team B | I11: =WEEKNUM(B11,2) -> 6 | J11: =IF(C11="","",WEEKNUM(C11,2)) | K11: =VLOOKUP(MONTH(B11),'03_Lookup'!A:B,2,FALSE) -> Feb | L11: =IF(C11="","",VLOOKUP(MONTH(C11),'03_Lookup'!A:B,2,FALSE))
A12: 9 | B12: 45330 | D12: Open | E12: Movie | F12: High | G12: Team A | I12: =WEEKNUM(B12,2) -> 6 | J12: =IF(C12="","",WEEKNUM(C12,2)) | K12: =VLOOKUP(MONTH(B12),'03_Lookup'!A:B,2,FALSE) -> Feb | L12: =IF(C12="","",VLOOKUP(MONTH(C12),'03_Lookup'!A:B,2,FALSE))
A13: 10 | B13: 45298 | C13: 45305 | D13: Closed | E13: Series | F13: Medium | G13: Team A | H13: 168 | I13: =WEEKNUM(B13,2) -> 1 | J13: =IF(C13="","",WEEKNUM(C13,2)) -> 2 | K13: =VLOOKUP(MONTH(B13),'03_Lookup'!A:B,2,FALSE) -> Jan | L13: =IF(C13="","",VLOOKUP(MONTH(C13),'03_Lookup'!A:B,2,FALSE)) -> Jan
A14: 11 | B14: 45344 | D14: Open | E14: Series | F14: Medium | G14: Team B | I14: =WEEKNUM(B14,2) -> 8 | J14: =IF(C14="","",WEEKNUM(C14,2)) | K14: =VLOOKUP(MONTH(B14),'03_Lookup'!A:B,2,FALSE) -> Feb | L14: =IF(C14="","",VLOOKUP(MONTH(C14),'03_Lookup'!A:B,2,FALSE))
A15: 12 | B15: 45304 | D15: Open | E15: Series | F15: Medium | G15: Team B | I15: =WEEKNUM(B15,2) -> 2 | J15: =IF(C15="","",WEEKNUM(C15,2)) | K15: =VLOOKUP(MONTH(B15),'03_Lookup'!A:B,2,FALSE) -> Jan | L15: =IF(C15="","",VLOOKUP(MONTH(C15),'03_Lookup'!A:B,2,FALSE))
A16: 13 | B16: 45324 | D16: Closed | E16: Series | F16: High | G16: Team B | H16: 48 | I16: =WEEKNUM(B16,2) -> 5 | J16: =IF(C16="","",WEEKNUM(C16,2)) | K16: =VLOOKUP(MONTH(B16),'03_Lookup'!A:B,2,FALSE) -> Feb | L16: =IF(C16="","",VLOOKUP(MONTH(C16),'03_Lookup'!A:B,2,FALSE))
A17: 14 | B17: 45353 | D17: Open | E17: Series | F17: Medium | G17: Team A | I17: =WEEKNUM(B17,2) -> 9 | J17: =IF(C17="","",WEEKNUM(C17,2)) | K17: =VLOOKUP(MONTH(B17),'03_Lookup'!A:B,2,FALSE) -> Mar | L17: =IF(C17="","",VLOOKUP(MONTH(C17),'03_Lookup'!A:B,2,FALSE))
A18: 15 | B18: 45338 | D18: Open | E18: Series | F18: Medium | G18: Team B | I18: =WEEKNUM(B18,2) -> 7 | J18: =IF(C18="","",WEEKNUM(C18,2)) | K18: =VLOOKUP(MONTH(B18),'03_Lookup'!A:B,2,FALSE) -> Feb | L18: =IF(C18="","",VLOOKUP(MONTH(C18),'03_Lookup'!A:B,2,FALSE))
A19: 16 | B19: 45300 | D19: Open | E19: Movie | F19: Medium | G19: Team A | I19: =WEEKNUM(B19,2) -> 2 | J19: =IF(C19="","",WEEKNUM(C19,2)) | K19: =VLOOKUP(MONTH(B19),'03_Lookup'!A:B,2,FALSE) -> Jan | L19: =IF(C19="","",VLOOKUP(MONTH(C19),'03_Lookup'!A:B,2,FALSE))
A20: 17 | B20: 45337 | D20: Open | E20: Series | F20: High | G20: Team A | I20: =WEEKNUM(B20,2) -> 7 | J20: =IF(C20="","",WEEKNUM(C20,2)) | K20: =VLOOKUP(MONTH(B20),'03_Lookup'!A:B,2,FALSE) -> Feb | L20: =IF(C20="","",VLOOKUP(MONTH(C20),'03_Lookup'!A:B,2,FALSE))
A21: 18 | B21: 45357 | D21: Open | E21: Series | F21: Medium | G21: Team A | I21: =WEEKNUM(B21,2) -> 10 | J21: =IF(C21="","",WEEKNUM(C21,2)) | K21: =VLOOKUP(MONTH(B21),'03_Lookup'!A:B,2,FALSE) -> Mar | L21: =IF(C21="","",VLOOKUP(MONTH(C21),'03_Lookup'!A:B,2,FALSE))
A22: 19 | B22: 45369 | D22: Open | E22: Movie | F22: Medium | G22: Team B | I22: =WEEKNUM(B22,2) -> 12 | J22: =IF(C22="","",WEEKNUM(C22,2)) | K22: =VLOOKUP(MONTH(B22),'03_Lookup'!A:B,2,FALSE) -> Mar | L22: =IF(C22="","",VLOOKUP(MONTH(C22),'03_Lookup'!A:B,2,FALSE))
A23: 20 | B23: 45299 | C23: 45300 | D23: Closed | E23: Movie | F23: High | G23: Team B | H23: 24 | I23: =WEEKNUM(B23,2) -> 2 | J23: =IF(C23="","",WEEKNUM(C23,2)) -> 2 | K23: =VLOOKUP(MONTH(B23),'03_Lookup'!A:B,2,FALSE) -> Jan | L23: =IF(C23="","",VLOOKUP(MONTH(C23),'03_Lookup'!A:B,2,FALSE)) -> Jan
A24: 21 | B24: 45298 | C24: 45296 | D24: Closed | E24: Movie | F24: Medium | G24: Team A | H24: 144 | I24: =WEEKNUM(B24,2) -> 1 | J24: =IF(C24="","",WEEKNUM(C24,2)) -> 1 | K24: =VLOOKUP(MONTH(B24),'03_Lookup'!A:B,2,FALSE) -> Jan | L24: =IF(C24="","",VLOOKUP(MONTH(C24),'03_Lookup'!A:B,2,FALSE)) -> Jan
A25: 22 | B25: 45310 | D25: Open | E25: Series | F25: High | G25: Team A | I25: =WEEKNUM(B25,2) -> 3 | J25: =IF(C25="","",WEEKNUM(C25,2)) | K25: =VLOOKUP(MONTH(B25),'03_Lookup'!A:B,2,FALSE) -> Jan | L25: =IF(C25="","",VLOOKUP(MONTH(C25),'03_Lookup'!A:B,2,FALSE))
A26: 23 | B26: 45309 | D26: Open | E26: Series | F26: Medium | G26: Team B | I26: =WEEKNUM(B26,2) -> 3 | J26: =IF(C26="","",WEEKNUM(C26,2)) | K26: =VLOOKUP(MONTH(B26),'03_Lookup'!A:B,2,FALSE) -> Jan | L26: =IF(C26="","",VLOOKUP(MONTH(C26),'03_Lookup'!A:B,2,FALSE))
A27: 24 | B27: 45376 | D27: Open | E27: Movie | F27: Medium | G27: Team B | I27: =WEEKNUM(B27,2) -> 13 | J27: =IF(C27="","",WEEKNUM(C27,2)) | K27: =VLOOKUP(MONTH(B27),'03_Lookup'!A:B,2,FALSE) -> Mar | L27: =IF(C27="","",VLOOKUP(MONTH(C27),'03_Lookup'!A:B,2,FALSE))
A28: 25 | B28: 45302 | C28: 45301 | D28: Closed | E28: Series | F28: High | G28: Team B | H28: 168 | I28: =WEEKNUM(B28,2) -> 2 | J28: =IF(C28="","",WEEKNUM(C28,2)) -> 2 | K28: =VLOOKUP(MONTH(B28),'03_Lookup'!A:B,2,FALSE) -> Jan | L28: =IF(C28="","",VLOOKUP(MONTH(C28),'03_Lookup'!A:B,2,FALSE)) -> Jan
A29: 26 | B29: 45298 | D29: Open | E29: Movie | F29: Low | G29: Team B | I29: =WEEKNUM(B29,2) -> 1 | J29: =IF(C29="","",WEEKNUM(C29,2)) | K29: =VLOOKUP(MONTH(B29),'03_Lookup'!A:B,2,FALSE) -> Jan | L29: =IF(C29="","",VLOOKUP(MONTH(C29),'03_Lookup'!A:B,2,FALSE))
A30: 27 | B30: 45323 | D30: Open | E30: Movie | F30: Low | G30: Team B | I30: =WEEKNUM(B30,2) -> 5 | J30: =IF(C30="","",WEEKNUM(C30,2)) | K30: =VLOOKUP(MONTH(B30),'03_Lookup'!A:B,2,FALSE) -> Feb | L30: =IF(C30="","",VLOOKUP(MONTH(C30),'03_Lookup'!A:B,2,FALSE))
A31: 28 | B31: 45348 | D31: Open | E31: Movie | F31: Medium | G31: Team A | I31: =WEEKNUM(B31,2) -> 9 | J31: =IF(C31="","",WEEKNUM(C31,2)) | K31: =VLOOKUP(MONTH(B31),'03_Lookup'!A:B,2,FALSE) -> Feb | L31: =IF(C31="","",VLOOKUP(MONTH(C31),'03_Lookup'!A:B,2,FALSE))
A32: 29 | B32: 45376 | D32: Open | E32: Series | F32: High | G32: Team B | I32: =WEEKNUM(B32,2) -> 13 | J32: =IF(C32="","",WEEKNUM(C32,2)) | K32: =VLOOKUP(MONTH(B32),'03_Lookup'!A:B,2,FALSE) -> Mar | L32: =IF(C32="","",VLOOKUP(MONTH(C32),'03_Lookup'!A:B,2,FALSE))
A33: 30 | B33: 45380 | D33: Open | E33: Movie | F33: Medium | G33: Team B | I33: =WEEKNUM(B33,2) -> 13 | J33: =IF(C33="","",WEEKNUM(C33,2)) | K33: =VLOOKUP(MONTH(B33),'03_Lookup'!A:B,2,FALSE) -> Mar | L33: =IF(C33="","",VLOOKUP(MONTH(C33),'03_Lookup'!A:B,2,FALSE))
A34: 31 | B34: 45334 | D34: Open | E34: Movie | F34: Medium | G34: Team A | I34: =WEEKNUM(B34,2) -> 7 | J34: =IF(C34="","",WEEKNUM(C34,2)) | K34: =VLOOKUP(MONTH(B34),'03_Lookup'!A:B,2,FALSE) -> Feb | L34: =IF(C34="","",VLOOKUP(MONTH(C34),'03_Lookup'!A:B,2,FALSE))
A35: 32 | B35: 45335 | D35: Open | E35: Series | F35: Medium | G35: Team A | I35: =WEEKNUM(B35,2) -> 7 | J35: =IF(C35="","",WEEKNUM(C35,2)) | K35: =VLOOKUP(MONTH(B35),'03_Lookup'!A:B,2,FALSE) -> Feb | L35: =IF(C35="","",VLOOKUP(MONTH(C35),'03_Lookup'!A:B,2,FALSE))
A36: 33 | B36: 45311 | D36: Open | E36: Series | F36: High | G36: Team B | I36: =WEEKNUM(B36,2) -> 3 | J36: =IF(C36="","",WEEKNUM(C36,2)) | K36: =VLOOKUP(MONTH(B36),'03_Lookup'!A:B,2,FALSE) -> Jan | L36: =IF(C36="","",VLOOKUP(MONTH(C36),'03_Lookup'!A:B,2,FALSE))
A37: 34 | B37: 45323 | D37: Open | E37: Series | F37: Medium | G37: Team A | I37: =WEEKNUM(B37,2) -> 5 | J37: =IF(C37="","",WEEKNUM(C37,2)) | K37: =VLOOKUP(MONTH(B37),'03_Lookup'!A:B,2,FALSE) -> Feb | L37: =IF(C37="","",VLOOKUP(MONTH(C37),'03_Lookup'!A:B,2,FALSE))
A38: 35 | B38: 45373 | D38: Open | E38: Movie | F38: Low | G38: Team B | I38: =WEEKNUM(B38,2) -> 12 | J38: =IF(C38="","",WEEKNUM(C38,2)) | K38: =VLOOKUP(MONTH(B38),'03_Lookup'!A:B,2,FALSE) -> Mar | L38: =IF(C38="","",VLOOKUP(MONTH(C38),'03_Lookup'!A:B,2,FALSE))
A39: 36 | B39: 45327 | C39: 45331 | D39: Closed | E39: Movie | F39: Medium | G39: Team B | H39: 96 | I39: =WEEKNUM(B39,2) -> 6 | J39: =IF(C39="","",WEEKNUM(C39,2)) -> 6 | K39: =VLOOKUP(MONTH(B39),'03_Lookup'!A:B,2,FALSE) -> Feb | L39: =IF(C39="","",VLOOKUP(MONTH(C39),'03_Lookup'!A:B,2,FALSE)) -> Feb
A40: 37 | B40: 45308 | C40: 45312 | D40: Closed | E40: Movie | F40: Medium | G40: Team A | H40: 96 | I40: =WEEKNUM(B40,2) -> 3 | J40: =IF(C40="","",WEEKNUM(C40,2)) -> 3 | K40: =VLOOKUP(MONTH(B40),'03_Lookup'!A:B,2,FALSE) -> Jan | L40: =IF(C40="","",VLOOKUP(MONTH(C40),'03_Lookup'!A:B,2,FALSE)) -> Jan
A41: 38 | B41: 45302 | C41: 45306 | D41: Closed | E41: Series | F41: Medium | G41: Team B | H41: 96 | I41: =WEEKNUM(B41,2) -> 2 | J41: =IF(C41="","",WEEKNUM(C41,2)) -> 3 | K41: =VLOOKUP(MONTH(B41),'03_Lookup'!A:B,2,FALSE) -> Jan | L41: =IF(C41="","",VLOOKUP(MONTH(C41),'03_Lookup'!A:B,2,FALSE)) -> Jan
...

Sheet 03_Lookup
A1: Lookup Table
A3: Resolution Month
A4: Month Number | B4: Month
A5: 1 | B5: Jan
A6: 2 | B6: Feb
A7: 3 | B7: Mar
A8: 4 | B8: Apr
A9: 5 | B9: May
A10: 6 | B10: Jun
A11: 7 | B11: Jul
A12: 8 | B12: Aug
A13: 9 | B13: Sep
A14: 10 | B14: Oct
A15: 11 | B15: Nov
A16: 12 | B16: Dec

Sheet 04_Analysis
A1: Operational Analysis
A3: Incoming Tickets by Week | D3: Completed Tickets by Week | G3: Weekly Capacity Analysis
A4: creation_week | B4: Incoming Tickets | D4: resolution_week | E4: Completed Tickets | G4: Analysis Week | H4: Incoming Tickets | I4: Completed Tickets | J4: Backlog Change | K4: Backlog
A5: 1 | B5: 31 | D5: 1 | E5: 3 | G5: 1 | H5: =IFERROR(_xlfn.XLOOKUP(A5,$A$5:$A$17,$B$5:$B$17),0) -> 31 | I5: =IFERROR(_xlfn.XLOOKUP(D5,$D$5:$D$18,$E$5:$E$18),0) -> 3 | J5: =H5-I5 -> 28 | K5: =J5 -> 28
A6: 2 | B6: 36 | D6: 2 | E6: 14 | G6: 2 | H6: =IFERROR(_xlfn.XLOOKUP(A6,$A$5:$A$17,$B$5:$B$17),0) -> 36 | I6: =IFERROR(_xlfn.XLOOKUP(D6,$D$5:$D$18,$E$5:$E$18),0) -> 14 | J6: =H6-I6 -> 22 | K6: =K5+J6 -> 50
A7: 3 | B7: 29 | D7: 3 | E7: 8 | G7: 3 | H7: =IFERROR(_xlfn.XLOOKUP(A7,$A$5:$A$17,$B$5:$B$17),0) -> 29 | I7: =IFERROR(_xlfn.XLOOKUP(D7,$D$5:$D$18,$E$5:$E$18),0) -> 8 | J7: =H7-I7 -> 21 | K7: =K6+J7 -> 71
A8: 4 | B8: 27 | D8: 4 | E8: 6 | G8: 4 | H8: =IFERROR(_xlfn.XLOOKUP(A8,$A$5:$A$17,$B$5:$B$17),0) -> 27 | I8: =IFERROR(_xlfn.XLOOKUP(D8,$D$5:$D$18,$E$5:$E$18),0) -> 6 | J8: =H8-I8 -> 21 | K8: =K7+J8 -> 92
A9: 5 | B9: 34 | D9: 5 | E9: 9 | G9: 5 | H9: =IFERROR(_xlfn.XLOOKUP(A9,$A$5:$A$17,$B$5:$B$17),0) -> 34 | I9: =IFERROR(_xlfn.XLOOKUP(D9,$D$5:$D$18,$E$5:$E$18),0) -> 9 | J9: =H9-I9 -> 25 | K9: =K8+J9 -> 117
A10: 6 | B10: 33 | D10: 6 | E10: 8 | G10: 6 | H10: =IFERROR(_xlfn.XLOOKUP(A10,$A$5:$A$17,$B$5:$B$17),0) -> 33 | I10: =IFERROR(_xlfn.XLOOKUP(D10,$D$5:$D$18,$E$5:$E$18),0) -> 8 | J10: =H10-I10 -> 25 | K10: =K9+J10 -> 142
A11: 7 | B11: 32 | D11: 7 | E11: 8 | G11: 7 | H11: =IFERROR(_xlfn.XLOOKUP(A11,$A$5:$A$17,$B$5:$B$17),0) -> 32 | I11: =IFERROR(_xlfn.XLOOKUP(D11,$D$5:$D$18,$E$5:$E$18),0) -> 8 | J11: =H11-I11 -> 24 | K11: =K10+J11 -> 166
A12: 8 | B12: 32 | D12: 8 | E12: 7 | G12: 8 | H12: =IFERROR(_xlfn.XLOOKUP(A12,$A$5:$A$17,$B$5:$B$17),0) -> 32 | I12: =IFERROR(_xlfn.XLOOKUP(D12,$D$5:$D$18,$E$5:$E$18),0) -> 7 | J12: =H12-I12 -> 25 | K12: =K11+J12 -> 191
A13: 9 | B13: 21 | D13: 9 | E13: 4 | G13: 9 | H13: =IFERROR(_xlfn.XLOOKUP(A13,$A$5:$A$17,$B$5:$B$17),0) -> 21 | I13: =IFERROR(_xlfn.XLOOKUP(D13,$D$5:$D$18,$E$5:$E$18),0) -> 4 | J13: =H13-I13 -> 17 | K13: =K12+J13 -> 208
A14: 10 | B14: 36 | D14: 10 | E14: 14 | G14: 10 | H14: =IFERROR(_xlfn.XLOOKUP(A14,$A$5:$A$17,$B$5:$B$17),0) -> 36 | I14: =IFERROR(_xlfn.XLOOKUP(D14,$D$5:$D$18,$E$5:$E$18),0) -> 14 | J14: =H14-I14 -> 22 | K14: =K13+J14 -> 230
A15: 11 | B15: 27 | D15: 11 | E15: 7 | G15: 11 | H15: =IFERROR(_xlfn.XLOOKUP(A15,$A$5:$A$17,$B$5:$B$17),0) -> 27 | I15: =IFERROR(_xlfn.XLOOKUP(D15,$D$5:$D$18,$E$5:$E$18),0) -> 7 | J15: =H15-I15 -> 20 | K15: =K14+J15 -> 250
A16: 12 | B16: 32 | D16: 12 | E16: 10 | G16: 12 | H16: =IFERROR(_xlfn.XLOOKUP(A16,$A$5:$A$17,$B$5:$B$17),0) -> 32 | I16: =IFERROR(_xlfn.XLOOKUP(D16,$D$5:$D$18,$E$5:$E$18),0) -> 10 | J16: =H16-I16 -> 22 | K16: =K15+J16 -> 272
A17: 13 | B17: 29 | D17: 13 | E17: 7 | G17: 13 | H17: =IFERROR(_xlfn.XLOOKUP(A17,$A$5:$A$17,$B$5:$B$17),0) -> 29 | I17: =IFERROR(_xlfn.XLOOKUP(D17,$D$5:$D$18,$E$5:$E$18),0) -> 7 | J17: =H17-I17 -> 22 | K17: =K16+J17 -> 294
A18: Total general | B18: 399 | D18: 14 | E18: 4 | G18: 14 | H18: =IFERROR(_xlfn.XLOOKUP(A18,$A$5:$A$17,$B$5:$B$17),0) -> 0 | I18: =IFERROR(_xlfn.XLOOKUP(D18,$D$5:$D$18,$E$5:$E$18),0) -> 4 | J18: =H18-I18 -> -4 | K18: =K17+J18 -> 290
D19: Total general | E19: 109
A21: Average Resolution Time by Ticket Type | D21: Open Tickets by Priority
A22: ticket_type | B22: Average Resolution Time (hrs) | D22: Cuenta de ticket_id | E22: status
A23: Movie | B23: 117.38182 | D23: priority | E23: Open | F23: Closed | G23: Total general
A24: Series | B24: 131.58621 | D24: High | E24: 46 | F24: 35 | G24: 81
A25: Total general | B25: 124.67257 | D25: Low | E25: 70 | F25: 26 | G25: 96
D26: Medium | E26: 170 | F26: 52 | G26: 222
D27: Total general | E27: 286 | F27: 113 | G27: 399

Sheet 05_Dashboard
N1: Ticket Operations Analysis Dashboard
Q4: Analysis Period: January–March
N7: Business Question
N8: Was the team able to keep up with incoming ticket demand?
N10: 399 | Q10: =SUM('04_Analysis'!E5:E18) -> 109 | T10: ='04_Analysis'!K18 -> 290 | W10: =IFERROR(__xludf.DUMMYFUNCTION("AVERAGE(FILTER('02_Prepared_Data'!H2:H400,'02_Prepared_Data'!H2:H400<>""""))"),124.672566371681) -> 124.67257
N12: Incoming Tickets | Q12: Completed Tickets | T12: Backlog | W12: Avg Resolution Time (hrs)
N13: Incoming vs Completed Tickets by Week
N33: Average Resolution Time by Ticket Type | T33: Open Tickets by Priority
